Workbook

Sheet CorST
A1: Слово | B1: Частота-CorST | C1: IPM-CorST | D1: Ранг-CorST | E1: Номер строки в RLC | F1: IPM-RLC
A2: в | B2: 35889 | C2: 11520.564 | D2: 1 | E2: =MATCH(A2,RLC!$A$2:$A$10993,0) -> 2 | F2: {=IFERROR(INDEX(RLC!$C$2:$C$10993,E2),"")} -> 37993.234
A3: и | B3: 31435 | C3: 10090.806 | D3: =IF(C3=C2,D2,D2+1) -> 2 | E3: =MATCH(A3,RLC!$A$2:$A$10993,0) -> 1 | F3: {=IFERROR(INDEX(RLC!$C$2:$C$10993,E3),"")} -> 38334.702
A4: на | B4: 13212 | C4: 4241.1239 | D4: =IF(C4=C3,D3,D3+1) -> 3 | E4: =MATCH(A4,RLC!$A$2:$A$10993,0) -> 4 | F4: {=IFERROR(INDEX(RLC!$C$2:$C$10993,E4),"")} -> 13265.412
A5: не | B5: 11811 | C5: 3791.3953 | D5: =IF(C5=C4,D4,D4+1) -> 4 | E5: =MATCH(A5,RLC!$A$2:$A$10993,0) -> 5 | F5: {=IFERROR(INDEX(RLC!$C$2:$C$10993,E5),"")} -> 12860.168
A6: с | B6: 11363 | C6: 3647.5848 | D6: =IF(C6=C5,D5,D5+1) -> 5 | E6: =MATCH(A6,RLC!$A$2:$A$10993,0) -> 7 | F6: {=IFERROR(INDEX(RLC!$C$2:$C$10993,E6),"")} -> 9178.432
A7: что | B7: 10265 | C7: 3295.1208 | D7: =IF(C7=C6,D6,D6+1) -> 6 | E7: =MATCH(A7,RLC!$A$2:$A$10993,0) -> 3 | F7: {=IFERROR(INDEX(RLC!$C$2:$C$10993,E7),"")} -> 16305.402
A8: как | B8: 7396 | C8: 2374.1562 | D8: =IF(C8=C7,D7,D7+1) -> 7 | E8: =MATCH(A8,RLC!$A$2:$A$10993,0) -> 8 | F8: {=IFERROR(INDEX(RLC!$C$2:$C$10993,E8),"")} -> 8273.6097
A9: к | B9: 6790 | C9: 2179.6269 | D9: =IF(C9=C8,D8,D8+1) -> 8 | E9: =MATCH(A9,RLC!$A$2:$A$10993,0) -> 14 | F9: {=IFERROR(INDEX(RLC!$C$2:$C$10993,E9),"")} -> 4742.0127
A10: а | B10: 5924 | C10: 1901.6362 | D10: =IF(C10=C9,D9,D9+1) -> 9 | E10: =MATCH(A10,RLC!$A$2:$A$10993,0) -> 19 | F10: {=IFERROR(INDEX(RLC!$C$2:$C$10993,E10),"")} -> 3449.2197
A11: для | B11: 5652 | C11: 1814.3227 | D11: =IF(C11=C10,D10,D10+1) -> 10 | E11: =MATCH(A11,RLC!$A$2:$A$10993,0) -> 13 | F11: {=IFERROR(INDEX(RLC!$C$2:$C$10993,E11),"")} -> 5009.0748
A12: по | B12: 5634 | C12: 1808.5447 | D12: =IF(C12=C11,D11,D11+1) -> 11 | E12: =MATCH(A12,RLC!$A$2:$A$10993,0) -> 15 | F12: {=IFERROR(INDEX(RLC!$C$2:$C$10993,E12),"")} -> 4641.034
A13: о | B13: 4912 | C13: 1576.7787 | D13: =IF(C13=C12,D12,D12+1) -> 12 | E13: =MATCH(A13,RLC!$A$2:$A$10993,0) -> 12 | F13: {=IFERROR(INDEX(RLC!$C$2:$C$10993,E13),"")} -> 5022.3615
A14: из | B14: 4365 | C14: 1401.1887 | D14: =IF(C14=C13,D13,D13+1) -> 13 | E14: =MATCH(A14,RLC!$A$2:$A$10993,0) -> 16 | F14: {=IFERROR(INDEX(RLC!$C$2:$C$10993,E14),"")} -> 4432.4333
... A1349: форм | B1349: 92 | C1349: 29.532501 | D1349: =IF(C1349=C1348,D1348,D1348+1) -> 464 | E1349: =MATCH(A1349,RLC!$A$2:$A$10993,0) -> 5288 | F1349: {=IFERROR(INDEX(RLC!$C$2:$C$10993,E1349),"")} -> 21.258673
A1350: школе | B1350: 92 | C1350: 29.532501 | D1350: =IF(C1350=C1349,D1349,D1349+1) -> 464 | E1350: =MATCH(A1350,RLC!$A$2:$A$10993,0) -> 403 | F1350: {=IFERROR(INDEX(RLC!$C$2:$C$10993,E1350),"")} -> 259.09008 | G1350: =C1350>E1350 -> FALSE
A1351: элементов | B1351: 92 | C1351: 29.532501 | D1351: =IF(C1351=C1350,D1350,D1350+1) -> 464 | E1351: =MATCH(A1351,RLC!$A$2:$A$10993,0) -> 4111 | F1351: {=IFERROR(INDEX(RLC!$C$2:$C$10993,E1351),"")} -> 27.902008
A1352: этими | B1352: 92 | C1352: 29.532501 | D1352: =IF(C1352=C1351,D1351,D1351+1) -> 464 | E1352: =MATCH(A1352,RLC!$A$2:$A$10993,0) -> 1491 | F1352: {=IFERROR(INDEX(RLC!$C$2:$C$10993,E1352),"")} -> 77.062689
A1353: артикля | B1353: 91 | C1353: 29.211495 | D1353: =IF(C1353=C1352,D1352,D1352+1) -> 465 | E1353: =MATCH(A1353,RLC!$A$2:$A$10993,0) -> #N/A | F1353: {=IFERROR(INDEX(RLC!$C$2:$C$10993,E1353),"")}
A1354: всему | B1354: 91 | C1354: 29.211495 | D1354: =IF(C1354=C1353,D1353,D1353+1) -> 465 | E1354: =MATCH(A1354,RLC!$A$2:$A$10993,0) -> 740 | F1354: {=IFERROR(INDEX(RLC!$C$2:$C$10993,E1354),"")} -> 144.82471
A1355: выполнения | B1355: 91 | C1355: 29.211495 | D1355: =IF(C1355=C1354,D1354,D1354+1) -> 465 | E1355: =MATCH(A1355,RLC!$A$2:$A$10993,0) -> #N/A | F1355: {=IFERROR(INDEX(RLC!$C$2:$C$10993,E1355),"")}
A1356: достоевский | B1356: 91 | C1356: 29.211495 | D1356: =IF(C1356=C1355,D1355,D1355+1) -> 465 | E1356: =MATCH(A1356,RLC!$A$2:$A$10993,0) -> #N/A | F1356: {=IFERROR(INDEX(RLC!$C$2:$C$10993,E1356),"")}
A1357: менеджмента | B1357: 91 | C1357: 29.211495 | D1357: =IF(C1357=C1356,D1356,D1356+1) -> 465 | E1357: =MATCH(A1357,RLC!$A$2:$A$10993,0) -> 2857 | F1357: {=IFERROR(INDEX(RLC!$C$2:$C$10993,E1357),"")} -> 39.860012
A1358: наша | B1358: 91 | C1358: 29.211495 | D1358: =IF(C1358=C1357,D1357,D1357+1) -> 465 | E1358: =MATCH(A1358,RLC!$A$2:$A$10993,0) -> 550 | F1358: {=IFERROR(INDEX(RLC!$C$2:$C$10993,E1358),"")} -> 193.98539
A1359: поднятая | B1359: 91 | C1359: 29.211495 | D1359: =IF(C1359=C1358,D1358,D1358+1) -> 465 | E1359: =MATCH(A1359,RLC!$A$2:$A$10993,0) -> #N/A | F1359: {=IFERROR(INDEX(RLC!$C$2:$C$10993,E1359),"")}
A1360: постепенно | B1360: 91 | C1360: 29.211495 | D1360: =IF(C1360=C1359,D1359,D1359+1) -> 465 | E1360: =MATCH(A1360,RLC!$A$2:$A$10993,0) -> 2468 | F1360: {=IFERROR(INDEX(RLC!$C$2:$C$10993,E1360),"")} -> 46.503347
A1361: рублей | B1361: 91 | C1361: 29.211495 | D1361: =IF(C1361=C1360,D1360,D1360+1) -> 465 | E1361: =MATCH(A1361,RLC!$A$2:$A$10993,0) -> 1696 | F1361: {=IFERROR(INDEX(RLC!$C$2:$C$10993,E1361),"")} -> 67.76202
A1362: сегодняшний | B1362: 91 | C1362: 29.211495 | D1362: =IF(C1362=C1361,D1361,D1361+1) -> 465 | E1362: =MATCH(A1362,RLC!$A$2:$A$10993,0) -> 1872 | F1362: {=IFERROR(INDEX(RLC!$C$2:$C$10993,E1362),"")} -> 62.447352
... A1716: чехов | B1716: 73 | C1716: 23.433397 | D1716: =IF(C1716=C1715,D1715,D1715+1) -> 483 | E1716: =MATCH(A1716,RLC!$A$2:$A$10993,0) -> #N/A | F1716: {=IFERROR(INDEX(RLC!$C$2:$C$10993,E1716),"")}
A1717: шапочка | B1717: 73 | C1717: 23.433397 | D1717: =IF(C1717=C1716,D1716,D1716+1) -> 483 | E1717: =MATCH(A1717,RLC!$A$2:$A$10993,0) -> 3339 | F1717: {=IFERROR(INDEX(RLC!$C$2:$C$10993,E1717),"")} -> 34.545343 | G1717: =C1717>E1717 -> FALSE
A1718: широко | B1718: 73 | C1718: 23.433397 | D1718: =IF(C1718=C1717,D1717,D1717+1) -> 483 | E1718: =MATCH(A1718,RLC!$A$2:$A$10993,0) -> 1584 | F1718: {=IFERROR(INDEX(RLC!$C$2:$C$10993,E1718),"")} -> 73.076688 | G1718: =C1718>E1718 -> FALSE
A1719: эмоций | B1719: 73 | C1719: 23.433397 | D1719: =IF(C1719=C1718,D1718,D1718+1) -> 483 | E1719: =MATCH(A1719,RLC!$A$2:$A$10993,0) -> 6912 | F1719: {=IFERROR(INDEX(RLC!$C$2:$C$10993,E1719),"")} -> 15.944005
A1720: большие | B1720: 72 | C1720: 23.112392 | D1720: =IF(C1720=C1719,D1719,D1719+1) -> 484 | E1720: =MATCH(A1720,RLC!$A$2:$A$10993,0) -> 836 | F1720: {=IFERROR(INDEX(RLC!$C$2:$C$10993,E1720),"")} -> 128.8807
A1721: большого | B1721: 72 | C1721: 23.112392 | D1721: =IF(C1721=C1720,D1720,D1720+1) -> 484 | E1721: =MATCH(A1721,RLC!$A$2:$A$10993,0) -> 2650 | F1721: {=IFERROR(INDEX(RLC!$C$2:$C$10993,E1721),"")} -> 42.517346
A1722: ведет | B1722: 72 | C1722: 23.112392 | D1722: =IF(C1722=C1721,D1721,D1721+1) -> 484 | E1722: =MATCH(A1722,RLC!$A$2:$A$10993,0) -> 3482 | F1722: {=IFERROR(INDEX(RLC!$C$2:$C$10993,E1722),"")} -> 31.888009
A1723: вниз | B1723: 72 | C1723: 23.112392 | D1723: =IF(C1723=C1722,D1722,D1722+1) -> 484 | E1723: =MATCH(A1723,RLC!$A$2:$A$10993,0) -> 2831 | F1723: {=IFERROR(INDEX(RLC!$C$2:$C$10993,E1723),"")} -> 39.860012
A1724: вузов | B1724: 72 | C1724: 23.112392 | D1724: =IF(C1724=C1723,D1723,D1723+1) -> 484 | E1724: =MATCH(A1724,RLC!$A$2:$A$10993,0) -> 6051 | F1724: {=IFERROR(INDEX(RLC!$C$2:$C$10993,E1724),"")} -> 17.272672
A1725: выражений | B1725: 72 | C1725: 23.112392 | D1725: =IF(C1725=C1724,D1724,D1724+1) -> 484 | E1725: =MATCH(A1725,RLC!$A$2:$A$10993,0) -> 3785 | F1725: {=IFERROR(INDEX(RLC!$C$2:$C$10993,E1725),"")} -> 29.230675
A1726: гражданским | B1726: 72 | C1726: 23.112392 | D1726: =IF(C1726=C1725,D1725,D1725+1) -> 484 | E1726: =MATCH(A1726,RLC!$A$2:$A$10993,0) -> #N/A | F1726: {=IFERROR(INDEX(RLC!$C$2:$C$10993,E1726),"")}
A1727: изучить | B1727: 72 | C1727: 23.112392 | D1727: =IF(C1727=C1726,D1726,D1726+1) -> 484 | E1727: =MATCH(A1727,RLC!$A$2:$A$10993,0) -> 4371 | F1727: {=IFERROR(INDEX(RLC!$C$2:$C$10993,E1727),"")} -> 25.244674
...

Sheet RLC
A1: Слово | B1: Частота-RLC | C1: IPM-RLC | D1: Ранг-RLC | E1: Номер строки в CorST
A2: и | B2: 28852 | C2: 38334.702 | D2: 1 | E2: =MATCH(A2,CorST!$A$2:$A$8126,0) -> 2
A3: в | B3: 28595 | C3: 37993.234 | D3: =IF(C3=C2,D2,D2+1) -> 2 | E3: =MATCH(A3,CorST!$A$2:$A$8126,0) -> 1
A4: что | B4: 12272 | C4: 16305.402 | D4: =IF(C4=C3,D3,D3+1) -> 3 | E4: =MATCH(A4,CorST!$A$2:$A$8126,0) -> 6
A5: на | B5: 9984 | C5: 13265.412 | D5: =IF(C5=C4,D4,D4+1) -> 4 | E5: =MATCH(A5,CorST!$A$2:$A$8126,0) -> 3
A6: не | B6: 9679 | C6: 12860.168 | D6: =IF(C6=C5,D5,D5+1) -> 5 | E6: =MATCH(A6,CorST!$A$2:$A$8126,0) -> 4
A7: я | B7: 8489 | C7: 11279.055 | D7: =IF(C7=C6,D6,D6+1) -> 6 | E7: =MATCH(A7,CorST!$A$2:$A$8126,0) -> 23
A8: с | B8: 6908 | C8: 9178.432 | D8: =IF(C8=C7,D7,D7+1) -> 7 | E8: =MATCH(A8,CorST!$A$2:$A$8126,0) -> 5
A9: как | B9: 6227 | C9: 8273.6097 | D9: =IF(C9=C8,D8,D8+1) -> 8 | E9: =MATCH(A9,CorST!$A$2:$A$8126,0) -> 7
A10: это | B10: 5389 | C10: 7160.1868 | D10: =IF(C10=C9,D9,D9+1) -> 9 | E10: =MATCH(A10,CorST!$A$2:$A$8126,0) -> 14
A11: но | B11: 4307 | C11: 5722.569 | D11: =IF(C11=C10,D10,D10+1) -> 10 | E11: =MATCH(A11,CorST!$A$2:$A$8126,0) -> 18
A12: он | B12: 4050 | C12: 5381.1016 | D12: =IF(C12=C11,D11,D11+1) -> 11 | E12: =MATCH(A12,CorST!$A$2:$A$8126,0) -> 20
A13: о | B13: 3780 | C13: 5022.3615 | D13: =IF(C13=C12,D12,D12+1) -> 12 | E13: =MATCH(A13,CorST!$A$2:$A$8126,0) -> 12
A14: для | B14: 3770 | C14: 5009.0748 | D14: =IF(C14=C13,D13,D13+1) -> 13 | E14: =MATCH(A14,CorST!$A$2:$A$8126,0) -> 10
... A8127: ориентировка | B8127: 10 | C8127: 13.286671 | D8127: =IF(C8127=C8126,D8126,D8126+1) -> 4565 | E8127: =MATCH(A8127,CorST!$A$2:$A$8126,0) -> #N/A

Sheet merge
A1: Слово | B1: IPM-CorST | C1: IPM-RLC
A2: сделка | B2: 11520.564
A3: сделать | B3: 10090.806 | C3: 361.39744
A4: сделаны | B4: 4241.1239
A5: сделано | B5: 3791.3953 | C5: 23.916007
A6: сделана | B6: 3647.5848 | C6: 15.944005
A7: сделан | B7: 3295.1208
A8: сделало | B8: 2374.1562 | C8: 27.902008
A9: сделали | B9: 2179.6269 | C9: 73.076688
A10: сделала | B10: 1901.6362 | C10: 51.818015
A11: сделал | B11: 1814.3227 | C11: 61.118685
A12: сделает | B12: 1808.5447 | C12: 25.244674
A13: сдачи | B13: 1576.7787
A14: сдать | B14: 1401.1887 | C14: 17.272672
A15: сдать | B15: 1398.9417 | C15: 17.272672
A16: сдаваться | B16: 1355.606 | C16: 13.286671
A17: священника | B17: 1228.4878
A18: священная | B18: 1162.6817 | C18: 37.202678
A19: святых | B19: 1154.9776
A20: святого | B20: 1134.4332
A21: связь | B21: 944.39801 | C21: 146.15338
A22: связывают | B22: 943.75599
A23: связывается | B23: 872.49279
A24: связывает | B24: 840.07124 | C24: 13.286671
A25: связность | B25: 814.0698
A26: связи | B26: 744.09061 | C26: 186.01339
A27: связей | B27: 742.48558 | C27: 33.216676
A28: связать | B28: 735.10246
A29: связаны | B29: 730.92939 | C29: 119.58003
A30: связанных | B30: 670.25936 | C30: 18.601339
A31: связано | B31: 670.25936 | C31: 93.006694
A32: связанный | B32: 652.60406
A33: связанные | B33: 638.47982 | C33: 50.489348
A34: связанны | B34: 605.09526 | C34: 17.272672
A35: связанную | B35: 601.5642
A36: связанной | B36: 559.51248 | C36: 18.601339
A37: связанное | B37: 553.73438
A38: связанного | B38: 548.27729
A39: связанная | B39: 544.10422
A40: связана | B40: 543.46221 | C40: 63.776019
...
